<?xml version="1.0" ?>
<!-- =================================================================================== -->
<!-- |    This document was autogenerated by xacro from ros_project.main.xacro         | -->
<!-- |    EDITING THIS FILE BY HAND IS NOT RECOMMENDED                                 | -->
<!-- =================================================================================== -->
<robot name="ros_project" xmlns:xacro="http://www.ros.org/wiki/xacro">
  <material name="red">
    <color rgba="0.8 0 0 1"/>
  </material>
  <material name="black">
    <color rgba="0 0 0 1"/>
  </material>
  <material name="green">
    <color rgba="0 1 0 1"/>
  </material>
  <gazebo reference="camera_link">
    <sensor name="camera1" type="camera">
      <update_rate>30.0</update_rate>
      <camera name="head">
        <horizontal_fov>1.3962634</horizontal_fov>
        <image>
          <width>800</width>
          <height>800</height>
          <format>R8G8B8</format>
        </image>
        <clip>
          <near>0.02</near>
          <far>300</far>
        </clip>
        <noise>
          <type>gaussian</type>
          <mean>0.0</mean>
          <stddev>0.007</stddev>
        </noise>
      </camera>
      <plugin filename="libgazebo_ros_camera.so" name="camera_controller">
        <alwaysOn>true</alwaysOn>
        <updateRate>0.0</updateRate>
        <cameraName>rrbot/camera1</cameraName>
        <imageTopicName>image_raw</imageTopicName>
        <cameraInfoTopicName>camera_info</cameraInfoTopicName>
        <frameName>camera_link</frameName>
        <hackBaseline>0.07</hackBaseline>
        <distortionK1>0.0</distortionK1>
        <distortionK2>0.0</distortionK2>
        <distortionK3>0.0</distortionK3>
        <distortionT1>0.0</distortionT1>
        <distortionT2>0.0</distortionT2>
      </plugin>
    </sensor>
  </gazebo>
  <link name="world"/>
  <link name="chassis_main">
    <visual>
      <geometry>
        <cylinder length="0.1" radius="0"/>
      </geometry>
      <origin rpy="0 0 0" xyz="0 0 0"/>
      <material name="red"/>
    </visual>
    <collision>
      <geometry>
        <cylinder length="0.1" radius="0"/>
      </geometry>
      <origin rpy="0 0 0" xyz="0 0 0"/>
    </collision>
  </link>
  <joint name="world_to_chassis_main" type="fixed">
    <parent link="world"/>
    <child link="chassis_main"/>
    <origin xyz="0 0.12 -0.05"/>
    <axis xyz="0 0 0"/>
  </joint>
  <inertial>
    <origin rpy="0 0 0" xyz="0 0 0"/>
    <mass value="1"/>
    <inertia ixx="1.0" ixy="0.0" ixz="0.0" iyy="1.0" iyz="0.0" izz="0.0"/>
  </inertial>
  <link name="wheel_left">
    <visual>
      <geometry>
        <cylinder length="0.05" radius="0"/>
      </geometry>
      <origin rpy="1.57075 0 0" xyz="0 0 0"/>
      <material name="black"/>
    </visual>
    <collision>
      <geometry>
        <cylinder length="0.05" radius="0"/>
      </geometry>
      <origin rpy="1.57075 0 0" xyz="0 0 0"/>
    </collision>
  </link>
  <joint name="base_to_wheel_left" type="continuous">
    <parent link="chassis_main"/>
    <child link="wheel_left"/>
    <origin xyz="0 0.12 -0.05"/>
    <axis xyz="0 1 0"/>
  </joint>
  <inertial>
    <origin rpy="0 0 0" xyz="0 0 0"/>
    <mass value="1"/>
    <inertia ixx="1.0" ixy="0.0" ixz="0.0" iyy="1.0" iyz="0.0" izz="0.0"/>
  </inertial>
  <link name="wheel_right">
    <visual>
      <geometry>
        <cylinder length="0.05" radius="0"/>
      </geometry>
      <origin rpy="1.57075 0 0" xyz="0 0 0"/>
      <material name="black"/>
    </visual>
    <collision>
      <geometry>
        <cylinder length="0.05" radius="0"/>
      </geometry>
      <origin rpy="1.57075 0 0" xyz="0 0 0"/>
    </collision>
  </link>
  <joint name="base_to_wheel_right" type="continuous">
    <parent link="chassis_main"/>
    <child link="wheel_right"/>
    <origin xyz="0 -0.12 -0.05"/>
    <axis xyz="0 1 0"/>
  </joint>
  <inertial>
    <origin rpy="0 0 0" xyz="0 0 0"/>
    <mass value="1"/>
    <inertia ixx="1.0" ixy="0.0" ixz="0.0" iyy="1.0" iyz="0.0" izz="0.0"/>
  </inertial>
  <link name="nub_back">
    <visual>
      <geometry>
        <sphere radius="0"/>
      </geometry>
      <origin rpy="0 0 0" xyz="0 0 0"/>
      <material name="green"/>
    </visual>
    <collision>
      <geometry>
        <sphere radius="0"/>
      </geometry>
      <origin rpy="0 0 0" xyz="0 0 0"/>
    </collision>
  </link>
  <joint name="base_to_nub_back" type="fixed">
    <parent link="chassis_main"/>
    <child link="nub_back"/>
    <origin xyz="-0.15 0 -0.025"/>
  </joint>
  <inertial>
    <origin rpy="0 0 0" xyz="0 0 0"/>
    <mass value="1"/>
    <inertia ixx="1.0" ixy="0.0" ixz="0.0" iyy="1.0" iyz="0.0" izz="0.0"/>
  </inertial>
  <link name="nub_front">
    <visual>
      <geometry>
        <sphere radius="0"/>
      </geometry>
      <origin rpy="0 0 0" xyz="0 0 0"/>
      <material name="green"/>
    </visual>
    <collision>
      <geometry>
        <sphere radius="0"/>
      </geometry>
      <origin rpy="0 0 0" xyz="0 0 0"/>
    </collision>
  </link>
  <joint name="base_to_nub_front" type="fixed">
    <parent link="chassis_main"/>
    <child link="nub_front"/>
    <origin xyz="0.15 0 -0.025"/>
  </joint>
  <inertial>
    <origin rpy="0 0 0" xyz="0 0 0"/>
    <mass value="1"/>
    <inertia ixx="1.0" ixy="0.0" ixz="0.0" iyy="1.0" iyz="0.0" izz="0.0"/>
  </inertial>
</robot>

<?xml version="1.0" ?>
<!-- =================================================================================== -->
<!-- |    This document was autogenerated by xacro from ros_project.main.xacro         | -->
<!-- |    EDITING THIS FILE BY HAND IS NOT RECOMMENDED                                 | -->
<!-- =================================================================================== -->
<robot name="ros_project" xmlns:xacro="http://www.ros.org/wiki/xacro">
  <material name="red">
    <color rgba="0.8 0 0 1"/>
  </material>
  <material name="black">
    <color rgba="0 0 0 1"/>
  </material>
  <material name="green">
    <color rgba="0 1 0 1"/>
  </material>
  <gazebo reference="camera_link">
    <sensor name="camera1" type="camera">
      <update_rate>30.0</update_rate>
      <camera name="head">
        <horizontal_fov>1.3962634</horizontal_fov>
        <image>
          <width>800</width>
          <height>800</height>
          <format>R8G8B8</format>
        </image>
        <clip>
          <near>0.02</near>
          <far>300</far>
        </clip>
        <noise>
          <type>gaussian</type>
          <mean>0.0</mean>
          <stddev>0.007</stddev>
        </noise>
      </camera>
      <plugin filename="libgazebo_ros_camera.so" name="camera_controller">
        <alwaysOn>true</alwaysOn>
        <updateRate>0.0</updateRate>
        <cameraName>rrbot/camera1</cameraName>
        <imageTopicName>image_raw</imageTopicName>
        <cameraInfoTopicName>camera_info</cameraInfoTopicName>
        <frameName>camera_link</frameName>
        <hackBaseline>0.07</hackBaseline>
        <distortionK1>0.0</distortionK1>
        <distortionK2>0.0</distortionK2>
        <distortionK3>0.0</distortionK3>
        <distortionT1>0.0</distortionT1>
        <distortionT2>0.0</distortionT2>
      </plugin>
    </sensor>
  </gazebo>
  <link name="world"/>
  <link name="chassis_main">
    <visual>
      <geometry>
        <cylinder length="0.1" radius="0"/>
      </geometry>
      <origin rpy="0 0 0" xyz="0 0 0"/>
      <material name="red"/>
    </visual>
    <collision>
      <geometry>
        <cylinder length="0.1" radius="0"/>
      </geometry>
      <origin rpy="0 0 0" xyz="0 0 0"/>
    </collision>
  </link>
  <joint name="world_to_chassis_main" type="fixed">
    <parent link="world"/>
    <child link="chassis_main"/>
    <origin xyz="0 0.12 -0.05"/>
    <axis xyz="0 0 0"/>
  </joint>
  <inertial>
    <origin rpy="0 0 0" xyz="0 0 0"/>
    <mass value="1"/>
    <inertia ixx="1.0" ixy="0.0" ixz="0.0" iyy="1.0" iyz="0.0" izz="0.0"/>
  </inertial>
  <link name="wheel_left">
    <visual>
      <geometry>
        <cylinder length="0.05" radius="0"/>
      </geometry>
      <origin rpy="1.57075 0 0" xyz="0 0 0"/>
      <material name="black"/>
    </visual>
    <collision>
      <geometry>
        <cylinder length="0.05" radius="0"/>
      </geometry>
      <origin rpy="1.57075 0 0" xyz="0 0 0"/>
    </collision>
  </link>
  <joint name="base_to_wheel_left" type="continuous">
    <parent link="chassis_main"/>
    <child link="wheel_left"/>
    <origin xyz="0 0.12 -0.05"/>
    <axis xyz="0 1 0"/>
  </joint>
  <inertial>
    <origin rpy="0 0 0" xyz="0 0 0"/>
    <mass value="1"/>
    <inertia ixx="1.0" ixy="0.0" ixz="0.0" iyy="1.0" iyz="0.0" izz="0.0"/>
  </inertial>
  <link name="wheel_right">
    <visual>
      <geometry>
        <cylinder length="0.05" radius="0"/>
      </geometry>
      <origin rpy="1.57075 0 0" xyz="0 0 0"/>
      <material name="black"/>
    </visual>
    <collision>
      <geometry>
        <cylinder length="0.05" radius="0"/>
      </geometry>
      <origin rpy="1.57075 0 0" xyz="0 0 0"/>
    </collision>
  </link>
  <joint name="base_to_wheel_right" type="continuous">
    <parent link="chassis_main"/>
    <child link="wheel_right"/>
    <origin xyz="0 -0.12 -0.05"/>
    <axis xyz="0 1 0"/>
  </joint>
  <inertial>
    <origin rpy="0 0 0" xyz="0 0 0"/>
    <mass value="1"/>
    <inertia ixx="1.0" ixy="0.0" ixz="0.0" iyy="1.0" iyz="0.0" izz="0.0"/>
  </inertial>
  <link name="nub_back">
    <visual>
      <geometry>
        <sphere radius="0"/>
      </geometry>
      <origin rpy="0 0 0" xyz="0 0 0"/>
      <material name="green"/>
    </visual>
    <collision>
      <geometry>
        <sphere radius="0"/>
      </geometry>
      <origin rpy="0 0 0" xyz="0 0 0"/>
    </collision>
  </link>
  <joint name="base_to_nub_back" type="fixed">
    <parent link="chassis_main"/>
    <child link="nub_back"/>
    <origin xyz="-0.15 0 -0.025"/>
  </joint>
  <inertial>
    <origin rpy="0 0 0" xyz="0 0 0"/>
    <mass value="1"/>
    <inertia ixx="1.0" ixy="0.0" ixz="0.0" iyy="1.0" iyz="0.0" izz="0.0"/>
  </inertial>
  <link name="nub_front">
    <visual>
      <geometry>
        <sphere radius="0"/>
      </geometry>
      <origin rpy="0 0 0" xyz="0 0 0"/>
      <material name="green"/>
    </visual>
    <collision>
      <geometry>
        <sphere radius="0"/>
      </geometry>
      <origin rpy="0 0 0" xyz="0 0 0"/>
    </collision>
  </link>
  <joint name="base_to_nub_front" type="fixed">
    <parent link="chassis_main"/>
    <child link="nub_front"/>
    <origin xyz="0.15 0 -0.025"/>
  </joint>
  <inertial>
    <origin rpy="0 0 0" xyz="0 0 0"/>
    <mass value="1"/>
    <inertia ixx="1.0" ixy="0.0" ixz="0.0" iyy="1.0" iyz="0.0" izz="0.0"/>
  </inertial>
</robot>

<?xml version="1.0" ?>
<!-- =================================================================================== -->
<!-- |    This document was autogenerated by xacro from ros_project.main.xacro         | -->
<!-- |    EDITING THIS FILE BY HAND IS NOT RECOMMENDED                                 | -->
<!-- =================================================================================== -->
<robot name="ros_project" xmlns:xacro="http://www.ros.org/wiki/xacro">
  <material name="red">
    <color rgba="0.8 0 0 1"/>
  </material>
  <material name="black">
    <color rgba="0 0 0 1"/>
  </material>
  <material name="green">
    <color rgba="0 1 0 1"/>
  </material>
  <gazebo reference="camera_link">
    <sensor name="camera1" type="camera">
      <update_rate>30.0</update_rate>
      <camera name="head">
        <horizontal_fov>1.3962634</horizontal_fov>
        <image>
          <width>800</width>
          <height>800</height>
          <format>R8G8B8</format>
        </image>
        <clip>
          <near>0.02</near>
          <far>300</far>
        </clip>
        <noise>
          <type>gaussian</type>
          <mean>0.0</mean>
          <stddev>0.007</stddev>
        </noise>
      </camera>
      <plugin filename="libgazebo_ros_camera.so" name="camera_controller">
        <alwaysOn>true</alwaysOn>
        <updateRate>0.0</updateRate>
        <cameraName>rrbot/camera1</cameraName>
        <imageTopicName>image_raw</imageTopicName>
        <cameraInfoTopicName>camera_info</cameraInfoTopicName>
        <frameName>camera_link</frameName>
        <hackBaseline>0.07</hackBaseline>
        <distortionK1>0.0</distortionK1>
        <distortionK2>0.0</distortionK2>
        <distortionK3>0.0</distortionK3>
        <distortionT1>0.0</distortionT1>
        <distortionT2>0.0</distortionT2>
      </plugin>
    </sensor>
  </gazebo>
  <link name="world"/>
  <link name="chassis_main">
    <visual>
      <geometry>
        <cylinder length="0.1" radius="0"/>
      </geometry>
      <origin rpy="0 0 0" xyz="0 0 0"/>
      <material name="red"/>
    </visual>
    <collision>
      <geometry>
        <cylinder length="0.1" radius="0"/>
      </geometry>
      <origin rpy="0 0 0" xyz="0 0 0"/>
    </collision>
  </link>
  <joint name="world_to_chassis_main" type="fixed">
    <parent link="world"/>
    <child link="chassis_main"/>
    <origin xyz="0 0.12 -0.05"/>
    <axis xyz="0 0 0"/>
  </joint>
  <inertial>
    <origin rpy="0 0 0" xyz="0 0 0"/>
    <mass value="1"/>
    <inertia ixx="1.0" ixy="0.0" ixz="0.0" iyy="1.0" iyz="0.0" izz="0.0"/>
  </inertial>
  <link name="wheel_left">
    <visual>
      <geometry>
        <cylinder length="0.05" radius="0"/>
      </geometry>
      <origin rpy="1.57075 0 0" xyz="0 0 0"/>
      <material name="black"/>
    </visual>
    <collision>
      <geometry>
        <cylinder length="0.05" radius="0"/>
      </geometry>
      <origin rpy="1.57075 0 0" xyz="0 0 0"/>
    </collision>
  </link>
  <joint name="base_to_wheel_left" type="continuous">
    <parent link="chassis_main"/>
    <child link="wheel_left"/>
    <origin xyz="0 0.12 -0.05"/>
    <axis xyz="0 1 0"/>
  </joint>
  <inertial>
    <origin rpy="0 0 0" xyz="0 0 0"/>
    <mass value="1"/>
    <inertia ixx="1.0" ixy="0.0" ixz="0.0" iyy="1.0" iyz="0.0" izz="0.0"/>
  </inertial>
  <link name="wheel_right">
    <visual>
      <geometry>
        <cylinder length="0.05" radius="0"/>
      </geometry>
      <origin rpy="1.57075 0 0" xyz="0 0 0"/>
      <material name="black"/>
    </visual>
    <collision>
      <geometry>
        <cylinder length="0.05" radius="0"/>
      </geometry>
      <origin rpy="1.57075 0 0" xyz="0 0 0"/>
    </collision>
  </link>
  <joint name="base_to_wheel_right" type="continuous">
    <parent link="chassis_main"/>
    <child link="wheel_right"/>
    <origin xyz="0 -0.12 -0.05"/>
    <axis xyz="0 1 0"/>
  </joint>
  <inertial>
    <origin rpy="0 0 0" xyz="0 0 0"/>
    <mass value="1"/>
    <inertia ixx="1.0" ixy="0.0" ixz="0.0" iyy="1.0" iyz="0.0" izz="0.0"/>
  </inertial>
  <link name="nub_back">
    <visual>
      <geometry>
        <sphere radius="0"/>
      </geometry>
      <origin rpy="0 0 0" xyz="0 0 0"/>
      <material name="green"/>
    </visual>
    <collision>
      <geometry>
        <sphere radius="0"/>
      </geometry>
      <origin rpy="0 0 0" xyz="0 0 0"/>
    </collision>
  </link>
  <joint name="base_to_nub_back" type="fixed">
    <parent link="chassis_main"/>
    <child link="nub_back"/>
    <origin xyz="-0.15 0 -0.025"/>
  </joint>
  <inertial>
    <origin rpy="0 0 0" xyz="0 0 0"/>
    <mass value="1"/>
    <inertia ixx="1.0" ixy="0.0" ixz="0.0" iyy="1.0" iyz="0.0" izz="0.0"/>
  </inertial>
  <link name="nub_front">
    <visual>
      <geometry>
        <sphere radius="0"/>
      </geometry>
      <origin rpy="0 0 0" xyz="0 0 0"/>
      <material name="green"/>
    </visual>
    <collision>
      <geometry>
        <sphere radius="0"/>
      </geometry>
      <origin rpy="0 0 0" xyz="0 0 0"/>
    </collision>
  </link>
  <joint name="base_to_nub_front" type="fixed">
    <parent link="chassis_main"/>
    <child link="nub_front"/>
    <origin xyz="0.15 0 -0.025"/>
  </joint>
  <inertial>
    <origin rpy="0 0 0" xyz="0 0 0"/>
    <mass value="1"/>
    <inertia ixx="1.0" ixy="0.0" ixz="0.0" iyy="1.0" iyz="0.0" izz="0.0"/>
  </inertial>
</robot>

